Workbook

Sheet README
A1: SPS Growth Model — Reference Spreadsheet
A3: Purpose
A4: Independent Excel implementation of Section 3 of the SPS Growth Model Requirements Document.
A5: This file is the authoritative reference the TypeScript simulation engine must match to the cent.
A6: The CI calibration test at reference/calibration/calibration.test.ts uses the CSV output.
A8: Scenario
A9: Source: scenario.illustrative.json (name: SPS Illustrative Scenario v0.1)
A10: Horizon: 10 years, base year 2026, 6 business lines.
A12: Decision policy (baseline)
A13: Rock allocation: held constant at the level required to operate each line at its initial capacity.
A14: Capital expenditure: zero for every line and every year.
A15: R&D spending: zero for every line and every year.
... A31: v1.0 — reference model built against scenario.illustrative.json.

Sheet Inputs
A1: Parameter | B1: 2026 | C1: 2027 | D1: 2028 | E1: 2029 | F1: 2030 | G1: 2031 | H1: 2032 | I1: 2033 | J1: 2034 | K1: 2035 | L1: 2036
A2: Corporate
A3: Tax rate (Tc) | B3: 0.27
A4: Cost of debt (rD) | B4: 0.06
A5: Cost of equity (rE) | B5: 0.146
A6: Equity 0 (E0, $M) | B6: 750
A7: Debt 0 (D0, $M) | B7: 750
A8: Leverage ceiling (Lmax) | B8: 2.5
A9: Terminal growth (gT) | B9: 0.025
A11: Depreciation ($M) | B11: 60 | C11: 65 | D11: 70 | E11: 78 | F11: 88 | G11: 100 | H11: 115 | I11: 130 | J11: 150 | K11: 170 | L11: 195
A12: Rock supply (kt) | B12: 1200 | C12: 1500 | D12: 1900 | E12: 2400 | F12: 3000 | G12: 3500 | H12: 4000 | I12: 4400 | J12: 4700 | K12: 4900 | L12: 5000
A13: Can raise debt | B13: 0 | C13: 0 | D13: 1 | E13: 1 | F13: 1 | G13: 1 | H13: 1 | I13: 1 | J13: 1 | K13: 1 | L13: 1
A15: Business Lines
A16: Parameter | B16: USS | C16: SPN | D16: FIS | E16: EMS | F16: ANS | G16: NPS
A17: Name | B17: Upstream Specialty Solutions and LFP | C17: Specialty Plant Nutrition | D17: Food and Industrial Salts Solutions | E17: Energy Materials Solutions | F17: Animal Nutrition Solutions | G17: Non-P Products Solutions
A18: Short code | B18: USS | C18: SPN | D18: FIS | E18: EMS | F18: ANS | G18: NPS
A19: Is legacy | B19: 0 | C19: 0 | D19: 0 | E19: 0 | F19: 1 | G19: 0
A20: Phase | B20: Exploratory | C20: Build | D20: Build | E20: Exploratory | F20: Run plus Growth | G20: Exploratory
A21: Yield (η) | B21: 0.45 | C21: 0.85 | D21: 0.75 | E21: 0.3 | F21: 0.9 | G21: 0.5
A22: Capex $/kt (κ) | B22: 8 | C22: 1 | D22: 5 | E22: 15 | F22: 0.5 | G22: 12
A23: Lead time (τ) | B23: 3 | C23: 1 | D23: 2 | E23: 3 | F23: 2 | G23: 4
A24: Cap depr (δ) | B24: 0.067 | C24: 0.067 | D24: 0.067 | E24: 0.067 | F24: 0.067 | G24: 0.067
A25: Base unit cost c0 ($M/kt) | B25: 1.7 | C25: 1.1 | D25: 1.6 | E25: 4.8 | F25: 0.6 | G25: 4.5
A26: Learning β | B26: 0.15 | C26: 0.12 | D26: 0.12 | E26: 0.2 | F26: 0.1 | G26: 0.18
A27: Base cum vol V0 (kt) | B27: 1500 | C27: 800 | D27: 200 | E27: 25 | F27: 3000 | G27: 50
A28: Base price p0 ($M/kt) | B28: 2 | C28: 1.5 | D28: 2 | E28: 6 | F28: 1 | G28: 6
A29: Price erosion π | B29: 0.01 | C29: 0.015 | D29: 0.02 | E29: 0.005 | F29: 0.025 | G29: 0.005
A30: R&D productivity μ | B30: 3 | C30: 4 | D30: 2.5 | E30: 3.5 | F30: 2 | G30: 2.5
A31: R&D lag λ | B31: 3 | C31: 2 | D31: 3 | E31: 4 | F31: 2 | G31: 4
A32: R&D conversion φ | B32: 0.2 | C32: 0.25 | D32: 0.2 | E32: 0.15 | F32: 0.25 | G32: 0.15
... A35: Initial pipeline P0 ($M) | B35: 40 | C35: 30 | D35: 15 | E35: 50 | F35: 20 | G35: 30
A37: Operating expenses ($M/yr)
A38: Year | B38: 2026 | C38: 2027 | D38: 2028 | E38: 2029 | F38: 2030 | G38: 2031 | H38: 2032 | I38: 2033 | J38: 2034 | K38: 2035 | L38: 2036
A39: USS | B39: 45 | C39: 48 | D39: 52 | E39: 56 | F39: 60 | G39: 65 | H39: 70 | I39: 75 | J39: 80 | K39: 85 | L39: 90
A40: SPN | B40: 20 | C40: 22 | D40: 25 | E40: 28 | F40: 32 | G40: 36 | H40: 40 | I40: 44 | J40: 48 | K40: 52 | L40: 56
A41: FIS | B41: 10 | C41: 12 | D41: 14 | E41: 17 | F41: 20 | G41: 23 | H41: 26 | I41: 29 | J41: 32 | K41: 35 | L41: 38
A42: EMS | B42: 5 | C42: 7 | D42: 10 | E42: 14 | F42: 19 | G42: 25 | H42: 32 | I42: 40 | J42: 48 | K42: 56 | L42: 65
A43: ANS | B43: 35 | C43: 38 | D43: 41 | E43: 44 | F43: 48 | G43: 52 | H43: 56 | I43: 60 | J43: 64 | K43: 68 | L43: 72
A44: NPS | B44: 8 | C44: 10 | D44: 12 | E44: 15 | F44: 18 | G44: 22 | H44: 26 | I44: 30 | J44: 34 | K44: 38 | L44: 42

Sheet Decisions
A1: Decision | B1: Line | C1: 2026 | D1: 2027 | E1: 2028 | F1: 2029 | G1: 2030 | H1: 2031 | I1: 2032 | J1: 2033 | K1: 2034 | L1: 2035 | M1: 2036
A2: Rock r (kt)
A3: r | B3: USS | C3: 522.2222 | D3: 522.2222 | E3: 522.2222 | F3: 522.2222 | G3: 522.2222 | H3: 522.2222 | I3: 522.2222 | J3: 522.2222 | K3: 522.2222 | L3: 522.2222 | M3: 522.2222
A4: r | B4: SPN | C4: 141.1765 | D4: 141.1765 | E4: 141.1765 | F4: 141.1765 | G4: 141.1765 | H4: 141.1765 | I4: 141.1765 | J4: 141.1765 | K4: 141.1765 | L4: 141.1765 | M4: 141.1765
A5: r | B5: FIS | C5: 53.3333 | D5: 53.3333 | E5: 53.3333 | F5: 53.3333 | G5: 53.3333 | H5: 53.3333 | I5: 53.3333 | J5: 53.3333 | K5: 53.3333 | L5: 53.3333 | M5: 53.3333
A6: r | B6: EMS | C6: 20 | D6: 20 | E6: 20 | F6: 20 | G6: 20 | H6: 20 | I6: 20 | J6: 20 | K6: 20 | L6: 20 | M6: 20
A7: r | B7: ANS | C7: 388.8889 | D7: 388.8889 | E7: 388.8889 | F7: 388.8889 | G7: 388.8889 | H7: 388.8889 | I7: 388.8889 | J7: 388.8889 | K7: 388.8889 | L7: 388.8889 | M7: 388.8889
A8: r | B8: NPS | C8: 24 | D8: 24 | E8: 24 | F8: 24 | G8: 24 | H8: 24 | I8: 24 | J8: 24 | K8: 24 | L8: 24 | M8: 24
A10: Capex I ($M)
A11: I | B11: USS | C11: 0 | D11: 0 | E11: 0 | F11: 0 | G11: 0 | H11: 0 | I11: 0 | J11: 0 | K11: 0 | L11: 0 | M11: 0
A12: I | B12: SPN | C12: 0 | D12: 0 | E12: 0 | F12: 0 | G12: 0 | H12: 0 | I12: 0 | J12: 0 | K12: 0 | L12: 0 | M12: 0
A13: I | B13: FIS | C13: 0 | D13: 0 | E13: 0 | F13: 0 | G13: 0 | H13: 0 | I13: 0 | J13: 0 | K13: 0 | L13: 0 | M13: 0
A14: I | B14: EMS | C14: 0 | D14: 0 | E14: 0 | F14: 0 | G14: 0 | H14: 0 | I14: 0 | J14: 0 | K14: 0 | L14: 0 | M14: 0
A15: I | B15: ANS | C15: 0 | D15: 0 | E15: 0 | F15: 0 | G15: 0 | H15: 0 | I15: 0 | J15: 0 | K15: 0 | L15: 0 | M15: 0
A16: I | B16: NPS | C16: 0 | D16: 0 | E16: 0 | F16: 0 | G16: 0 | H16: 0 | I16: 0 | J16: 0 | K16: 0 | L16: 0 | M16: 0
A18: R&D R ($M)
A19: R | B19: USS | C19: 0 | D19: 0 | E19: 0 | F19: 0 | G19: 0 | H19: 0 | I19: 0 | J19: 0 | K19: 0 | L19: 0 | M19: 0
A20: R | B20: SPN | C20: 0 | D20: 0 | E20: 0 | F20: 0 | G20: 0 | H20: 0 | I20: 0 | J20: 0 | K20: 0 | L20: 0 | M20: 0
A21: R | B21: FIS | C21: 0 | D21: 0 | E21: 0 | F21: 0 | G21: 0 | H21: 0 | I21: 0 | J21: 0 | K21: 0 | L21: 0 | M21: 0
A22: R | B22: EMS | C22: 0 | D22: 0 | E22: 0 | F22: 0 | G22: 0 | H22: 0 | I22: 0 | J22: 0 | K22: 0 | L22: 0 | M22: 0
A23: R | B23: ANS | C23: 0 | D23: 0 | E23: 0 | F23: 0 | G23: 0 | H23: 0 | I23: 0 | J23: 0 | K23: 0 | L23: 0 | M23: 0
A24: R | B24: NPS | C24: 0 | D24: 0 | E24: 0 | F24: 0 | G24: 0 | H24: 0 | I24: 0 | J24: 0 | K24: 0 | L24: 0 | M24: 0

Sheet Dynamics
A1: Line | B1: Variable | C1: 2026 | D1: 2027 | E1: 2028 | F1: 2029 | G1: 2030 | H1: 2031 | I1: 2032 | J1: 2033 | K1: 2034 | L1: 2035 | M1: 2036
A2: USS | B2: K | C2: =Inputs!B34 -> 235 | D2: =(1-Inputs!B24)*C2 -> 219.255 | E2: =(1-Inputs!B24)*D2 -> 204.56492 | F2: =(1-Inputs!B24)*E2 -> 190.85907 | G2: =(1-Inputs!B24)*F2+(Decisions!C11)/Inputs!B22 -> 178.07151 | H2: =(1-Inputs!B24)*G2+(Decisions!D11)/Inputs!B22 -> 166.14072 | I2: =(1-Inputs!B24)*H2+(Decisions!E11)/Inputs!B22 -> 155.00929 | J2: =(1-Inputs!B24)*I2+(Decisions!F11)/Inputs!B22 -> 144.62367 | K2: =(1-Inputs!B24)*J2+(Decisions!G11)/Inputs!B22 -> 134.93388 | L2: =(1-Inputs!B24)*K2+(Decisions!H11)/Inputs!B22 -> 125.89331 | M2: =(1-Inputs!B24)*L2+(Decisions!I11)/Inputs!B22 -> 117.45846
B3: Q | C3: =MIN(C2,Inputs!B21*Decisions!C3) -> 234.99999 | D3: =MIN(D2,Inputs!B21*Decisions!D3) -> 219.255 | E3: =MIN(E2,Inputs!B21*Decisions!E3) -> 204.56492 | F3: =MIN(F2,Inputs!B21*Decisions!F3) -> 190.85907 | G3: =MIN(G2,Inputs!B21*Decisions!G3) -> 178.07151 | H3: =MIN(H2,Inputs!B21*Decisions!H3) -> 166.14072 | I3: =MIN(I2,Inputs!B21*Decisions!I3) -> 155.00929 | J3: =MIN(J2,Inputs!B21*Decisions!J3) -> 144.62367 | K3: =MIN(K2,Inputs!B21*Decisions!K3) -> 134.93388 | L3: =MIN(L2,Inputs!B21*Decisions!L3) -> 125.89331 | M3: =MIN(M2,Inputs!B21*Decisions!M3) -> 117.45846
B4: V | C4: =Inputs!B27 -> 1500 | D4: =C4+C3 -> 1735 | E4: =D4+D3 -> 1954.255 | F4: =E4+E3 -> 2158.8199 | G4: =F4+F3 -> 2349.679 | H4: =G4+G3 -> 2527.7505 | I4: =H4+H3 -> 2693.8912 | J4: =I4+I3 -> 2848.9005 | K4: =J4+J3 -> 2993.5242 | ... M4: =L4+L3 -> 3254.3513
B5: c | C5: =Inputs!B25*(C4/Inputs!B27)^(-Inputs!B26) -> 1.7 | D5: =Inputs!B25*(D4/Inputs!B27)^(-Inputs!B26) -> 1.6632889 | E5: =Inputs!B25*(E4/Inputs!B27)^(-Inputs!B26) -> 1.6338622 | F5: =Inputs!B25*(F4/Inputs!B27)^(-Inputs!B26) -> 1.6096452 | G5: =Inputs!B25*(G4/Inputs!B27)^(-Inputs!B26) -> 1.5893199 | H5: =Inputs!B25*(H4/Inputs!B27)^(-Inputs!B26) -> 1.5719998 | I5: =Inputs!B25*(I4/Inputs!B27)^(-Inputs!B26) -> 1.5570609 | J5: =Inputs!B25*(J4/Inputs!B27)^(-Inputs!B26) -> 1.5440488 | K5: =Inputs!B25*(K4/Inputs!B27)^(-Inputs!B26) -> 1.5326225 | L5: =Inputs!B25*(L4/Inputs!B27)^(-Inputs!B26) -> 1.5225202 | M5: =Inputs!B25*(M4/Inputs!B27)^(-Inputs!B26) -> 1.5135367
B6: p | C6: =Inputs!B28 -> 2 | D6: =C6*(1-Inputs!B29)+C8/MAX(C3,1) -> 1.98 | E6: =D6*(1-Inputs!B29)+D8/MAX(D3,1) -> 1.9602 | F6: =E6*(1-Inputs!B29)+E8/MAX(E3,1) -> 1.940598 | G6: =F6*(1-Inputs!B29)+F8/MAX(F3,1) -> 1.9631078 | H6: =G6*(1-Inputs!B29)+G8/MAX(G3,1) -> 1.9884025 | I6: =H6*(1-Inputs!B29)+H8/MAX(H3,1) -> 2.0166704 | J6: =I6*(1-Inputs!B29)+I8/MAX(I3,1) -> 2.0481135 | K6: =J6*(1-Inputs!B29)+J8/MAX(J3,1) -> 2.0718851 | L6: =K6*(1-Inputs!B29)+K8/MAX(K3,1) -> 2.0867393 | M6: =L6*(1-Inputs!B29)+L8/MAX(L3,1) -> 2.0912902
B7: P | C7: =Inputs!B35 -> 40 | D7: =MAX(0,C7+Inputs!B30*Decisions!C19) -> 40 | E7: =MAX(0,D7+Inputs!B30*Decisions!D19) -> 40 | F7: =MAX(0,E7+Inputs!B30*Decisions!E19) -> 40 | G7: =MAX(0,F7+Inputs!B30*Decisions!F19-Inputs!B32*C7) -> 32 | H7: =MAX(0,G7+Inputs!B30*Decisions!G19-Inputs!B32*D7) -> 24 | I7: =MAX(0,H7+Inputs!B30*Decisions!H19-Inputs!B32*E7) -> 16 | J7: =MAX(0,I7+Inputs!B30*Decisions!I19-Inputs!B32*F7) -> 8 | K7: =MAX(0,J7+Inputs!B30*Decisions!J19-Inputs!B32*G7) -> 1.6 | L7: =MAX(0,K7+Inputs!B30*Decisions!K19-Inputs!B32*H7) -> 0 | M7: =MAX(0,L7+Inputs!B30*Decisions!L19-Inputs!B32*I7) -> 0
B8: dRev | C8: 0 | D8: 0 | E8: 0 | F8: =Inputs!B32*C7 -> 8 | G8: =Inputs!B32*D7 -> 8 | H8: =Inputs!B32*E7 -> 8 | I8: =Inputs!B32*F7 -> 8 | J8: =Inputs!B32*G7 -> 6.4 | K8: =Inputs!B32*H7 -> 4.8 | L8: =Inputs!B32*I7 -> 3.2 | M8: =Inputs!B32*J7 -> 1.6
B9: Rev | C9: =C6*C3 -> 469.99998 | D9: =D6*D3 -> 434.1249 | E9: =E6*E3 -> 400.98815 | F9: =F6*F3 -> 370.38072 | G9: =G6*G3 -> 349.57356 | H9: =H6*H3 -> 330.35461 | I9: =I6*I3 -> 312.60264 | J9: =J6*J3 -> 296.20568 | ... M9: =M6*M3 -> 245.63973
B10: COGS | C10: =C5*C3 -> 399.49998 | D10: =D5*D3 -> 364.68441 | E10: =E5*E3 -> 334.23088 | F10: =F5*F3 -> 307.21537 | G10: =G5*G3 -> 283.0126 | H10: =H5*H3 -> 261.17317 | I10: =I5*I3 -> 241.35891 | J10: =J5*J3 -> 223.306 | ... M10: =M5*M3 -> 177.77768
B11: EBITDA | C11: =C9-C10-Inputs!B39-Decisions!C19 -> 25.499997 | D11: =D9-D10-Inputs!C39-Decisions!D19 -> 21.440493 | E11: =E9-E10-Inputs!D39-Decisions!E19 -> 14.757264 | F11: =F9-F10-Inputs!E39-Decisions!F19 -> 7.1653497 | G11: =G9-G10-Inputs!F39-Decisions!G19 -> 6.5609628 | H11: =H9-H10-Inputs!G39-Decisions!H19 -> 4.1814404 | I11: =I9-I10-Inputs!H39-Decisions!I19 -> 1.2437381 | J11: =J9-J10-Inputs!I39-Decisions!J19 -> -2.1003136 | ... M11: =M9-M10-Inputs!L39-Decisions!M19 -> -22.137956
A13: SPN | B13: K | C13: =Inputs!C34 -> 120 | D13: =(1-Inputs!C24)*C13 -> 111.96 | E13: =(1-Inputs!C24)*D13+(Decisions!C12)/Inputs!C22 -> 104.45868 | F13: =(1-Inputs!C24)*E13+(Decisions!D12)/Inputs!C22 -> 97.459948 | G13: =(1-Inputs!C24)*F13+(Decisions!E12)/Inputs!C22 -> 90.930132 | H13: =(1-Inputs!C24)*G13+(Decisions!F12)/Inputs!C22 -> 84.837813 | I13: =(1-Inputs!C24)*H13+(Decisions!G12)/Inputs!C22 -> 79.15368 | J13: =(1-Inputs!C24)*I13+(Decisions!H12)/Inputs!C22 -> 73.850383 | K13: =(1-Inputs!C24)*J13+(Decisions!I12)/Inputs!C22 -> 68.902407 | L13: =(1-Inputs!C24)*K13+(Decisions!J12)/Inputs!C22 -> 64.285946 | M13: =(1-Inputs!C24)*L13+(Decisions!K12)/Inputs!C22 -> 59.978788
B14: Q | C14: =MIN(C13,Inputs!C21*Decisions!C4) -> 120 | D14: =MIN(D13,Inputs!C21*Decisions!D4) -> 111.96 | E14: =MIN(E13,Inputs!C21*Decisions!E4) -> 104.45868 | F14: =MIN(F13,Inputs!C21*Decisions!F4) -> 97.459948 | G14: =MIN(G13,Inputs!C21*Decisions!G4) -> 90.930132 | H14: =MIN(H13,Inputs!C21*Decisions!H4) -> 84.837813 | I14: =MIN(I13,Inputs!C21*Decisions!I4) -> 79.15368 | J14: =MIN(J13,Inputs!C21*Decisions!J4) -> 73.850383 | K14: =MIN(K13,Inputs!C21*Decisions!K4) -> 68.902407 | L14: =MIN(L13,Inputs!C21*Decisions!L4) -> 64.285946 | M14: =MIN(M13,Inputs!C21*Decisions!M4) -> 59.978788
B15: V | C15: =Inputs!C27 -> 800 | D15: =C15+C14 -> 920 | E15: =D15+D14 -> 1031.96 | F15: =E15+E14 -> 1136.4187 | G15: =F15+F14 -> 1233.8786 | H15: =G15+G14 -> 1324.8088 | I15: =H15+H14 -> 1409.6466 | J15: =I15+I14 -> 1488.8003 | K15: =J15+J14 -> 1562.6506 | ... M15: =L15+L14 -> 1695.839
B16: c | C16: =Inputs!C25*(C15/Inputs!C27)^(-Inputs!C26) -> 1.1 | D16: =Inputs!C25*(D15/Inputs!C27)^(-Inputs!C26) -> 1.0817053 | E16: =Inputs!C25*(E15/Inputs!C27)^(-Inputs!C26) -> 1.0669006 | F16: =Inputs!C25*(F15/Inputs!C27)^(-Inputs!C26) -> 1.054627 | G16: =Inputs!C25*(G15/Inputs!C27)^(-Inputs!C26) -> 1.0442652 | H16: =Inputs!C25*(H15/Inputs!C27)^(-Inputs!C26) -> 1.0353927 | I16: =Inputs!C25*(I15/Inputs!C27)^(-Inputs!C26) -> 1.0277092 | J16: =Inputs!C25*(J15/Inputs!C27)^(-Inputs!C26) -> 1.0209938 | K16: =Inputs!C25*(K15/Inputs!C27)^(-Inputs!C26) -> 1.0150795 | L16: =Inputs!C25*(L15/Inputs!C27)^(-Inputs!C26) -> 1.0098371 | M16: =Inputs!C25*(M15/Inputs!C27)^(-Inputs!C26) -> 1.0051649
B17: p | C17: =Inputs!C28 -> 1.5 | D17: =C17*(1-Inputs!C29)+C19/MAX(C14,1) -> 1.4775 | E17: =D17*(1-Inputs!C29)+D19/MAX(D14,1) -> 1.4553375 | F17: =E17*(1-Inputs!C29)+E19/MAX(E14,1) -> 1.5053062 | G17: =F17*(1-Inputs!C29)+F19/MAX(F14,1) -> 1.5596813 | H17: =G17*(1-Inputs!C29)+G19/MAX(G14,1) -> 1.6187669 | I17: =H17*(1-Inputs!C29)+H19/MAX(H14,1) -> 1.6607884 | J17: =I17*(1-Inputs!C29)+I19/MAX(I14,1) -> 1.6832528 | K17: =J17*(1-Inputs!C29)+J19/MAX(J14,1) -> 1.6833932 | L17: =K17*(1-Inputs!C29)+K19/MAX(K14,1) -> 1.6649454 | M17: =L17*(1-Inputs!C29)+L19/MAX(L14,1) -> 1.6399712
B18: P | C18: =Inputs!C35 -> 30 | D18: =MAX(0,C18+Inputs!C30*Decisions!C20) -> 30 | E18: =MAX(0,D18+Inputs!C30*Decisions!D20) -> 30 | F18: =MAX(0,E18+Inputs!C30*Decisions!E20-Inputs!C32*C18) -> 22.5 | G18: =MAX(0,F18+Inputs!C30*Decisions!F20-Inputs!C32*D18) -> 15 | H18: =MAX(0,G18+Inputs!C30*Decisions!G20-Inputs!C32*E18) -> 7.5 | I18: =MAX(0,H18+Inputs!C30*Decisions!H20-Inputs!C32*F18) -> 1.875 | J18: =MAX(0,I18+Inputs!C30*Decisions!I20-Inputs!C32*G18) -> 0 | K18: =MAX(0,J18+Inputs!C30*Decisions!J20-Inputs!C32*H18) -> 0 | L18: =MAX(0,K18+Inputs!C30*Decisions!K20-Inputs!C32*I18) -> 0 | M18: =MAX(0,L18+Inputs!C30*Decisions!L20-Inputs!C32*J18) -> 0
B19: dRev | C19: 0 | D19: 0 | E19: =Inputs!C32*C18 -> 7.5 | F19: =Inputs!C32*D18 -> 7.5 | G19: =Inputs!C32*E18 -> 7.5 | H19: =Inputs!C32*F18 -> 5.625 | I19: =Inputs!C32*G18 -> 3.75 | J19: =Inputs!C32*H18 -> 1.875 | K19: =Inputs!C32*I18 -> 0.46875 | L19: =Inputs!C32*J18 -> 0 | M19: =Inputs!C32*K18 -> 0
B20: Rev | C20: =C17*C14 -> 180 | D20: =D17*D14 -> 165.4209 | E20: =E17*E14 -> 152.02263 | F20: =F17*F14 -> 146.70706 | G20: =G17*G14 -> 141.82202 | H20: =H17*H14 -> 137.33265 | I20: =I17*I14 -> 131.45752 | J20: =J17*J14 -> 124.30886 | ... M20: =M17*M14 -> 98.363484
B21: COGS | C21: =C16*C14 -> 132 | D21: =D16*D14 -> 121.10772 | E21: =E16*E14 -> 111.44702 | F21: =F16*F14 -> 102.78389 | G21: =G16*G14 -> 94.955169 | H21: =H16*H14 -> 87.840453 | I21: =I16*I14 -> 81.346967 | J21: =J16*J14 -> 75.400784 | ... M21: =M16*M14 -> 60.288574
B22: EBITDA | C22: =C20-C21-Inputs!B40-Decisions!C20 -> 28 | D22: =D20-D21-Inputs!C40-Decisions!D20 -> 22.313178 | E22: =E20-E21-Inputs!D40-Decisions!E20 -> 15.575611 | F22: =F20-F21-Inputs!E40-Decisions!F20 -> 15.923169 | G22: =G20-G21-Inputs!F40-Decisions!G20 -> 14.866853 | H22: =H20-H21-Inputs!G40-Decisions!H20 -> 13.492195 | I22: =I20-I21-Inputs!H40-Decisions!I20 -> 10.110548 | J22: =J20-J21-Inputs!I40-Decisions!J20 -> 4.9080792 | ... M22: =M20-M21-Inputs!L40-Decisions!M20 -> -17.92509
A24: FIS | B24: K | C24: =Inputs!D34 -> 40 | D24: =(1-Inputs!D24)*C24 -> 37.32 | E24: =(1-Inputs!D24)*D24 -> 34.81956 | F24: =(1-Inputs!D24)*E24+(Decisions!C13)/Inputs!D22 -> 32.486649 | G24: =(1-Inputs!D24)*F24+(Decisions!D13)/Inputs!D22 -> 30.310044 | H24: =(1-Inputs!D24)*G24+(Decisions!E13)/Inputs!D22 -> 28.279271 | I24: =(1-Inputs!D24)*H24+(Decisions!F13)/Inputs!D22 -> 26.38456 | J24: =(1-Inputs!D24)*I24+(Decisions!G13)/Inputs!D22 -> 24.616794 | K24: =(1-Inputs!D24)*J24+(Decisions!H13)/Inputs!D22 -> 22.967469 | L24: =(1-Inputs!D24)*K24+(Decisions!I13)/Inputs!D22 -> 21.428649 | M24: =(1-Inputs!D24)*L24+(Decisions!J13)/Inputs!D22 -> 19.992929
B25: Q | C25: =MIN(C24,Inputs!D21*Decisions!C5) -> 39.999975 | D25: =MIN(D24,Inputs!D21*Decisions!D5) -> 37.32 | E25: =MIN(E24,Inputs!D21*Decisions!E5) -> 34.81956 | F25: =MIN(F24,Inputs!D21*Decisions!F5) -> 32.486649 | G25: =MIN(G24,Inputs!D21*Decisions!G5) -> 30.310044 | H25: =MIN(H24,Inputs!D21*Decisions!H5) -> 28.279271 | I25: =MIN(I24,Inputs!D21*Decisions!I5) -> 26.38456 | J25: =MIN(J24,Inputs!D21*Decisions!J5) -> 24.616794 | K25: =MIN(K24,Inputs!D21*Decisions!K5) -> 22.967469 | L25: =MIN(L24,Inputs!D21*Decisions!L5) -> 21.428649 | M25: =MIN(M24,Inputs!D21*Decisions!M5) -> 19.992929
B26: V | C26: =Inputs!D27 -> 200 | D26: =C26+C25 -> 239.99998 | E26: =D26+D25 -> 277.31997 | F26: =E26+E25 -> 312.13954 | G26: =F26+F25 -> 344.62618 | H26: =G26+G25 -> 374.93623 | I26: =H26+H25 -> 403.2155 | J26: =I26+I25 -> 429.60006 | K26: =J26+J25 -> 454.21685 | ... M26: =L26+L25 -> 498.61297
B27: c | C27: =Inputs!D25*(C26/Inputs!D27)^(-Inputs!D26) -> 1.6 | D27: =Inputs!D25*(D26/Inputs!D27)^(-Inputs!D26) -> 1.5653744 | E27: =Inputs!D25*(E26/Inputs!D27)^(-Inputs!D26) -> 1.5384587 | F27: =Inputs!D25*(F26/Inputs!D27)^(-Inputs!D26) -> 1.516777 | G27: =Inputs!D25*(G26/Inputs!D27)^(-Inputs!D26) -> 1.4988625 | H27: =Inputs!D25*(H26/Inputs!D27)^(-Inputs!D26) -> 1.4837772 | I27: =Inputs!D25*(I26/Inputs!D27)^(-Inputs!D26) -> 1.4708863 | J27: =Inputs!D25*(J26/Inputs!D27)^(-Inputs!D26) -> 1.4597412 | K27: =Inputs!D25*(K26/Inputs!D27)^(-Inputs!D26) -> 1.4500133 | L27: =Inputs!D25*(L26/Inputs!D27)^(-Inputs!D26) -> 1.4414555 | M27: =Inputs!D25*(M26/Inputs!D27)^(-Inputs!D26) -> 1.4338772
B28: p | C28: =Inputs!D28 -> 2 | D28: =C28*(1-Inputs!D29)+C30/MAX(C25,1) -> 1.96 | E28: =D28*(1-Inputs!D29)+D30/MAX(D25,1) -> 1.9208 | F28: =E28*(1-Inputs!D29)+E30/MAX(E25,1) -> 1.882384 | G28: =F28*(1-Inputs!D29)+F30/MAX(F25,1) -> 1.9370819 | H28: =G28*(1-Inputs!D29)+G30/MAX(G25,1) -> 1.9973174 | I28: =H28*(1-Inputs!D29)+H30/MAX(H25,1) -> 2.0634558 | J28: =I28*(1-Inputs!D29)+I30/MAX(I25,1) -> 2.1358896 | K28: =J28*(1-Inputs!D29)+J30/MAX(J25,1) -> 2.1906662 | L28: =K28*(1-Inputs!D29)+K30/MAX(K25,1) -> 2.2252246 | M28: =L28*(1-Inputs!D29)+L30/MAX(L25,1) -> 2.2367199
B29: P | C29: =Inputs!D35 -> 15 | D29: =MAX(0,C29+Inputs!D30*Decisions!C21) -> 15 | E29: =MAX(0,D29+Inputs!D30*Decisions!D21) -> 15 | F29: =MAX(0,E29+Inputs!D30*Decisions!E21) -> 15 | G29: =MAX(0,F29+Inputs!D30*Decisions!F21-Inputs!D32*C29) -> 12 | H29: =MAX(0,G29+Inputs!D30*Decisions!G21-Inputs!D32*D29) -> 9 | I29: =MAX(0,H29+Inputs!D30*Decisions!H21-Inputs!D32*E29) -> 6 | J29: =MAX(0,I29+Inputs!D30*Decisions!I21-Inputs!D32*F29) -> 3 | K29: =MAX(0,J29+Inputs!D30*Decisions!J21-Inputs!D32*G29) -> 0.6 | L29: =MAX(0,K29+Inputs!D30*Decisions!K21-Inputs!D32*H29) -> 0 | M29: =MAX(0,L29+Inputs!D30*Decisions!L21-Inputs!D32*I29) -> 0
B30: dRev | C30: 0 | D30: 0 | E30: 0 | F30: =Inputs!D32*C29 -> 3 | G30: =Inputs!D32*D29 -> 3 | H30: =Inputs!D32*E29 -> 3 | I30: =Inputs!D32*F29 -> 3 | J30: =Inputs!D32*G29 -> 2.4 | K30: =Inputs!D32*H29 -> 1.8 | L30: =Inputs!D32*I29 -> 1.2 | M30: =Inputs!D32*J29 -> 0.6
B31: Rev | C31: =C28*C25 -> 79.99995 | D31: =D28*D25 -> 73.1472 | E31: =E28*E25 -> 66.881411 | F31: =F28*F25 -> 61.152349 | G31: =G28*G25 -> 58.713039 | H31: =H28*H25 -> 56.48268 | I31: =I28*I25 -> 54.443374 | J31: =J28*J25 -> 52.578754 | ... M31: =M28*M25 -> 44.718583
B32: COGS | C32: =C27*C25 -> 63.99996 | D32: =D27*D25 -> 58.419774 | E32: =E27*E25 -> 53.568455 | F32: =F27*F25 -> 49.275002 | G32: =G27*G25 -> 45.430588 | H32: =H27*H25 -> 41.960138 | I32: =I27*I25 -> 38.808689 | J32: =J27*J25 -> 35.934149 | ... M32: =M27*M25 -> 28.667405
B33: EBITDA | C33: =C31-C32-Inputs!B41-Decisions!C21 -> 5.99999 | D33: =D31-D32-Inputs!C41-Decisions!D21 -> 2.7274259 | E33: =E31-E32-Inputs!D41-Decisions!E21 -> -0.68704438 | F33: =F31-F32-Inputs!E41-Decisions!F21 -> -5.1226529 | G33: =G31-G32-Inputs!F41-Decisions!G21 -> -6.7175488 | H33: =H31-H32-Inputs!G41-Decisions!H21 -> -8.4774575 | I33: =I31-I32-Inputs!H41-Decisions!I21 -> -10.365315 | J33: =J31-J32-Inputs!I41-Decisions!J21 -> -12.355394 | ... M33: =M31-M32-Inputs!L41-Decisions!M21 -> -21.948822
A35: EMS | B35: K | C35: =Inputs!E34 -> 6 | D35: =(1-Inputs!E24)*C35 -> 5.598 | E35: =(1-Inputs!E24)*D35 -> 5.222934 | F35: =(1-Inputs!E24)*E35 -> 4.8729974 | G35: =(1-Inputs!E24)*F35+(Decisions!C14)/Inputs!E22 -> 4.5465066 | H35: =(1-Inputs!E24)*G35+(Decisions!D14)/Inputs!E22 -> 4.2418907 | I35: =(1-Inputs!E24)*H35+(Decisions!E14)/Inputs!E22 -> 3.957684 | J35: =(1-Inputs!E24)*I35+(Decisions!F14)/Inputs!E22 -> 3.6925192 | K35: =(1-Inputs!E24)*J35+(Decisions!G14)/Inputs!E22 -> 3.4451204 | L35: =(1-Inputs!E24)*K35+(Decisions!H14)/Inputs!E22 -> 3.2142973 | M35: =(1-Inputs!E24)*L35+(Decisions!I14)/Inputs!E22 -> 2.9989394
B36: Q | C36: =MIN(C35,Inputs!E21*Decisions!C6) -> 6 | D36: =MIN(D35,Inputs!E21*Decisions!D6) -> 5.598 | E36: =MIN(E35,Inputs!E21*Decisions!E6) -> 5.222934 | F36: =MIN(F35,Inputs!E21*Decisions!F6) -> 4.8729974 | G36: =MIN(G35,Inputs!E21*Decisions!G6) -> 4.5465066 | H36: =MIN(H35,Inputs!E21*Decisions!H6) -> 4.2418907 | I36: =MIN(I35,Inputs!E21*Decisions!I6) -> 3.957684 | J36: =MIN(J35,Inputs!E21*Decisions!J6) -> 3.6925192 | K36: =MIN(K35,Inputs!E21*Decisions!K6) -> 3.4451204 | L36: =MIN(L35,Inputs!E21*Decisions!L6) -> 3.2142973 | M36: =MIN(M35,Inputs!E21*Decisions!M6) -> 2.9989394
B37: V | C37: =Inputs!E27 -> 25 | D37: =C37+C36 -> 31 | E37: =D37+D36 -> 36.598 | F37: =E37+E36 -> 41.820934 | G37: =F37+F36 -> 46.693931 | H37: =G37+G36 -> 51.240438 | I37: =H37+H36 -> 55.482329 | J37: =I37+I36 -> 59.440013 | K37: =J37+J36 -> 63.132532 | ... M37: =L37+L36 -> 69.791949
B38: c | C38: =Inputs!E25*(C37/Inputs!E27)^(-Inputs!E26) -> 4.8 | D38: =Inputs!E25*(D37/Inputs!E27)^(-Inputs!E26) -> 4.5978722 | E38: =Inputs!E25*(E37/Inputs!E27)^(-Inputs!E26) -> 4.4477234 | F38: =Inputs!E25*(F37/Inputs!E27)^(-Inputs!E26) -> 4.3306242 | G38: =Inputs!E25*(G37/Inputs!E27)^(-Inputs!E26) -> 4.2362068 | H38: =Inputs!E25*(H37/Inputs!E27)^(-Inputs!E26) -> 4.1582124 | I38: =Inputs!E25*(I37/Inputs!E27)^(-Inputs!E26) -> 4.0925906 | J38: =Inputs!E25*(J37/Inputs!E27)^(-Inputs!E26) -> 4.036579 | K38: =Inputs!E25*(K37/Inputs!E27)^(-Inputs!E26) -> 3.9882153 | L38: =Inputs!E25*(L37/Inputs!E27)^(-Inputs!E26) -> 3.9460587 | M38: =Inputs!E25*(M37/Inputs!E27)^(-Inputs!E26) -> 3.9090225
B39: p | C39: =Inputs!E28 -> 6 | D39: =C39*(1-Inputs!E29)+C41/MAX(C36,1) -> 5.97 | E39: =D39*(1-Inputs!E29)+D41/MAX(D36,1) -> 5.94015 | F39: =E39*(1-Inputs!E29)+E41/MAX(E36,1) -> 5.9104493 | G39: =F39*(1-Inputs!E29)+F41/MAX(F36,1) -> 5.880897 | H39: =G39*(1-Inputs!E29)+G41/MAX(G36,1) -> 7.5011107 | I39: =H39*(1-Inputs!E29)+H41/MAX(H36,1) -> 9.2316847 | J39: =I39*(1-Inputs!E29)+I41/MAX(I36,1) -> 11.080574 | K39: =J39*(1-Inputs!E29)+J41/MAX(J36,1) -> 13.056305 | L39: =K39*(1-Inputs!E29)+K41/MAX(K36,1) -> 15.168015 | M39: =L39*(1-Inputs!E29)+L41/MAX(L36,1) -> 17.075502
B40: P | C40: =Inputs!E35 -> 50 | D40: =MAX(0,C40+Inputs!E30*Decisions!C22) -> 50 | E40: =MAX(0,D40+Inputs!E30*Decisions!D22) -> 50 | F40: =MAX(0,E40+Inputs!E30*Decisions!E22) -> 50 | G40: =MAX(0,F40+Inputs!E30*Decisions!F22) -> 50 | H40: =MAX(0,G40+Inputs!E30*Decisions!G22-Inputs!E32*C40) -> 42.5 | I40: =MAX(0,H40+Inputs!E30*Decisions!H22-Inputs!E32*D40) -> 35 | J40: =MAX(0,I40+Inputs!E30*Decisions!I22-Inputs!E32*E40) -> 27.5 | K40: =MAX(0,J40+Inputs!E30*Decisions!J22-Inputs!E32*F40) -> 20 | L40: =MAX(0,K40+Inputs!E30*Decisions!K22-Inputs!E32*G40) -> 12.5 | M40: =MAX(0,L40+Inputs!E30*Decisions!L22-Inputs!E32*H40) -> 6.125
B41: dRev | C41: 0 | D41: 0 | E41: 0 | F41: 0 | G41: =Inputs!E32*C40 -> 7.5 | H41: =Inputs!E32*D40 -> 7.5 | I41: =Inputs!E32*E40 -> 7.5 | J41: =Inputs!E32*F40 -> 7.5 | K41: =Inputs!E32*G40 -> 7.5 | L41: =Inputs!E32*H40 -> 6.375 | M41: =Inputs!E32*I40 -> 5.25
B42: Rev | C42: =C39*C36 -> 36 | D42: =D39*D36 -> 33.42006 | E42: =E39*E36 -> 31.025011 | F42: =F39*F36 -> 28.801604 | G42: =G39*G36 -> 26.737537 | H42: =H39*H36 -> 31.818891 | I42: =I39*I36 -> 36.536091 | J42: =J39*J36 -> 40.915232 | ... M42: =M39*M36 -> 51.208394
B43: COGS | C43: =C38*C36 -> 28.8 | D43: =D38*D36 -> 25.738889 | E43: =E38*E36 -> 23.230166 | F43: =F38*F36 -> 21.10312 | G43: =G38*G36 -> 19.259942 | H43: =H38*H36 -> 17.638682 | I43: =I38*I36 -> 16.19718 | J43: =J38*J36 -> 14.905145 | ... M43: =M38*M36 -> 11.722922
...

Sheet Financials
A1: Metric | B1: 2026 | C1: 2027 | D1: 2028 | E1: 2029 | F1: 2030 | G1: 2031 | H1: 2032 | I1: 2033 | J1: 2034 | K1: 2035 | L1: 2036
A2: EBITDA USS ($M) | B2: =Dynamics!C11 -> 25.499997 | C2: =Dynamics!D11 -> 21.440493 | D2: =Dynamics!E11 -> 14.757264 | E2: =Dynamics!F11 -> 7.1653497 | F2: =Dynamics!G11 -> 6.5609628 | G2: =Dynamics!H11 -> 4.1814404 | H2: =Dynamics!I11 -> 1.2437381 | I2: =Dynamics!J11 -> -2.1003136 | ... L2: =Dynamics!M11 -> -22.137956
A3: EBITDA SPN ($M) | B3: =Dynamics!C22 -> 28 | C3: =Dynamics!D22 -> 22.313178 | D3: =Dynamics!E22 -> 15.575611 | E3: =Dynamics!F22 -> 15.923169 | F3: =Dynamics!G22 -> 14.866853 | G3: =Dynamics!H22 -> 13.492195 | H3: =Dynamics!I22 -> 10.110548 | I3: =Dynamics!J22 -> 4.9080792 | ... L3: =Dynamics!M22 -> -17.92509
A4: EBITDA FIS ($M) | B4: =Dynamics!C33 -> 5.99999 | C4: =Dynamics!D33 -> 2.7274259 | D4: =Dynamics!E33 -> -0.68704438 | E4: =Dynamics!F33 -> -5.1226529 | F4: =Dynamics!G33 -> -6.7175488 | G4: =Dynamics!H33 -> -8.4774575 | H4: =Dynamics!I33 -> -10.365315 | I4: =Dynamics!J33 -> -12.355394 | ... L4: =Dynamics!M33 -> -21.948822
A5: EBITDA EMS ($M) | B5: =Dynamics!C44 -> 2.2 | C5: =Dynamics!D44 -> 0.68117115 | D5: =Dynamics!E44 -> -2.2051542 | E5: =Dynamics!F44 -> -6.3015164 | F5: =Dynamics!G44 -> -11.522405 | G5: =Dynamics!H44 -> -10.819791 | H5: =Dynamics!I44 -> -11.66109 | I5: =Dynamics!J44 -> -13.989914 | ... L5: =Dynamics!M44 -> -25.514528
A6: EBITDA ANS ($M) | B6: =Dynamics!C55 -> 105 | C6: =Dynamics!D55 -> 86.606414 | D6: =Dynamics!E55 -> 69.505298 | E6: =Dynamics!F55 -> 58.336105 | F6: =Dynamics!G55 -> 46.953548 | G6: =Dynamics!H55 -> 36.32055 | H6: =Dynamics!I55 -> 25.223595 | I6: =Dynamics!J55 -> 13.716273 | ... L6: =Dynamics!M55 -> -21.443567
A7: EBITDA NPS ($M) | B7: =Dynamics!C66 -> 10 | C7: =Dynamics!D66 -> 8.3716288 | D7: =Dynamics!E66 -> 6.1601901 | E7: =Dynamics!F66 -> 2.62558 | F7: =Dynamics!G66 -> -1.091364 | G7: =Dynamics!H66 -> -1.7093619 | H7: =Dynamics!I66 -> -2.6765542 | I7: =Dynamics!J66 -> -3.9386123 | ... L7: =Dynamics!M66 -> -9.7519273
A8: EBITDA total ($M) | B8: =SUM(B2:B7) -> 176.69999 | C8: =SUM(C2:C7) -> 142.14031 | D8: =SUM(D2:D7) -> 103.10616 | E8: =SUM(E2:E7) -> 72.626035 | F8: =SUM(F2:F7) -> 49.050047 | G8: =SUM(G2:G7) -> 32.987575 | H8: =SUM(H2:H7) -> 11.874922 | I8: =SUM(I2:I7) -> -13.759882 | ... L8: =SUM(L2:L7) -> -118.72189
A9: Revenue total ($M) | B9: =Dynamics!C9+Dynamics!C20+Dynamics!C31+Dynamics!C42+Dynamics!C53+Dynamics!C64 -> 1187.9999 | C9: =Dynamics!D9+Dynamics!D20+Dynamics!D31+Dynamics!D42+Dynamics!D53+Dynamics!D64 -> 1091.3394 | D9: =Dynamics!E9+Dynamics!E20+Dynamics!E31+Dynamics!E42+Dynamics!E53+Dynamics!E64 -> 1002.5952 | E9: =Dynamics!F9+Dynamics!F20+Dynamics!F31+Dynamics!F42+Dynamics!F53+Dynamics!F64 -> 932.7773 | F9: =Dynamics!G9+Dynamics!G20+Dynamics!G31+Dynamics!G42+Dynamics!G53+Dynamics!G64 -> 878.89954 | G9: =Dynamics!H9+Dynamics!H20+Dynamics!H31+Dynamics!H42+Dynamics!H53+Dynamics!H64 -> 840.62058 | H9: =Dynamics!I9+Dynamics!I20+Dynamics!I31+Dynamics!I42+Dynamics!I53+Dynamics!I64 -> 802.66394 | I9: =Dynamics!J9+Dynamics!J20+Dynamics!J31+Dynamics!J42+Dynamics!J53+Dynamics!J64 -> 765.00171 | ... L9: =Dynamics!M9+Dynamics!M20+Dynamics!M31+Dynamics!M42+Dynamics!M53+Dynamics!M64 -> 643.76037
A10: Capex total ($M) | B10: =Decisions!C11+Decisions!C12+Decisions!C13+Decisions!C14+Decisions!C15+Decisions!C16 -> 0 | C10: =Decisions!D11+Decisions!D12+Decisions!D13+Decisions!D14+Decisions!D15+Decisions!D16 -> 0 | D10: =Decisions!E11+Decisions!E12+Decisions!E13+Decisions!E14+Decisions!E15+Decisions!E16 -> 0 | E10: =Decisions!F11+Decisions!F12+Decisions!F13+Decisions!F14+Decisions!F15+Decisions!F16 -> 0 | F10: =Decisions!G11+Decisions!G12+Decisions!G13+Decisions!G14+Decisions!G15+Decisions!G16 -> 0 | G10: =Decisions!H11+Decisions!H12+Decisions!H13+Decisions!H14+Decisions!H15+Decisions!H16 -> 0 | H10: =Decisions!I11+Decisions!I12+Decisions!I13+Decisions!I14+Decisions!I15+Decisions!I16 -> 0 | I10: =Decisions!J11+Decisions!J12+Decisions!J13+Decisions!J14+Decisions!J15+Decisions!J16 -> 0 | ... L10: =Decisions!M11+Decisions!M12+Decisions!M13+Decisions!M14+Decisions!M15+Decisions!M16 -> 0
A11: Depreciation ($M) | B11: =Inputs!B11 -> 60 | C11: =Inputs!C11 -> 65 | D11: =Inputs!D11 -> 70 | E11: =Inputs!E11 -> 78 | F11: =Inputs!F11 -> 88 | G11: =Inputs!G11 -> 100 | H11: =Inputs!H11 -> 115 | I11: =Inputs!I11 -> 130 | ... L11: =Inputs!L11 -> 195
A12: FCF ($M) | B12: =B8*(1-Inputs!B3)+Inputs!B3*B11-B10 -> 145.19099 | C12: =C8*(1-Inputs!B3)+Inputs!B3*C11-C10 -> 121.31243 | D12: =D8*(1-Inputs!B3)+Inputs!B3*D11-D10 -> 94.1675 | E12: =E8*(1-Inputs!B3)+Inputs!B3*E11-E10 -> 74.077005 | F12: =F8*(1-Inputs!B3)+Inputs!B3*F11-F10 -> 59.566534 | G12: =G8*(1-Inputs!B3)+Inputs!B3*G11-G10 -> 51.08093 | H12: =H8*(1-Inputs!B3)+Inputs!B3*H11-H10 -> 39.718693 | I12: =I8*(1-Inputs!B3)+Inputs!B3*I11-I10 -> 25.055286 | J12: =J8*(1-Inputs!B3)+Inputs!B3*J11-J10 -> 7.980073 | K12: =K8*(1-Inputs!B3)+Inputs!B3*K11-K10 -> -11.954781 | L12: =L8*(1-Inputs!B3)+Inputs!B3*L11-L10 -> -34.01698
A14: V0 ($M) | B14: =Inputs!B6+Inputs!B7 -> 1500
A15: WACC | B15: =(Inputs!B6/B14)*Inputs!B5+(Inputs!B7/B14)*Inputs!B4*(1-Inputs!B3) -> 0.0949
A17: Discount factor | B17: 1 | C17: =1/(1+$B$15)^1 -> 0.91332542 | D17: =1/(1+$B$15)^2 -> 0.83416332 | E17: =1/(1+$B$15)^3 -> 0.76186256 | F17: =1/(1+$B$15)^4 -> 0.69582844 | G17: =1/(1+$B$15)^5 -> 0.6355178 | H17: =1/(1+$B$15)^6 -> 0.58043456 | I17: =1/(1+$B$15)^7 -> 0.53012564 | J17: =1/(1+$B$15)^8 -> 0.48417722 | K17: =1/(1+$B$15)^9 -> 0.44221136 | L17: =1/(1+$B$15)^10 -> 0.40388288
A18: Discounted FCF ($M) | B18: =B12*B17 -> 145.19099 | C18: =C12*C17 -> 110.79772 | D18: =D12*D17 -> 78.551074 | E18: =E12*E17 -> 56.436497 | F18: =F12*F17 -> 41.448089 | G18: =G12*G17 -> 32.46284 | H18: =H12*H17 -> 23.054102 | I18: =I12*I17 -> 13.28245 | ... L18: =L12*L17 -> -13.738876
A20: Terminal growth gT | B20: =Inputs!B9 -> 0.025
A21: FCF T+1 ($M) | B21: =L12*(1+Inputs!B9) -> -34.867405
A22: Terminal value TV_T ($M) | B22: =B21/($B$15-Inputs!B9) -> -498.81838
A23: Discounted TV ($M) | B23: =B22*L17 -> -201.4642
A25: NPV excl. TV ($M) | B25: =SUM(C18:L18) -> 340.87113
A26: NPV incl. TV ($M) | B26: =B25+B23 -> 139.40693

Sheet Outputs
A1: Year | B1: 2026 | C1: 2027 | D1: 2028 | E1: 2029 | F1: 2030 | G1: 2031 | H1: 2032 | I1: 2033 | J1: 2034 | K1: 2035 | L1: 2036
A2: Rock supply (kt) | B2: =Inputs!B12 -> 1200 | C2: =Inputs!C12 -> 1500 | D2: =Inputs!D12 -> 1900 | E2: =Inputs!E12 -> 2400 | F2: =Inputs!F12 -> 3000 | G2: =Inputs!G12 -> 3500 | H2: =Inputs!H12 -> 4000 | I2: =Inputs!I12 -> 4400 | ... L2: =Inputs!L12 -> 5000
A3: Rock allocated total (kt) | B3: =Decisions!C3+Decisions!C4+Decisions!C5+Decisions!C6+Decisions!C7+Decisions!C8 -> 1149.6209 | C3: =Decisions!D3+Decisions!D4+Decisions!D5+Decisions!D6+Decisions!D7+Decisions!D8 -> 1149.6209 | D3: =Decisions!E3+Decisions!E4+Decisions!E5+Decisions!E6+Decisions!E7+Decisions!E8 -> 1149.6209 | E3: =Decisions!F3+Decisions!F4+Decisions!F5+Decisions!F6+Decisions!F7+Decisions!F8 -> 1149.6209 | F3: =Decisions!G3+Decisions!G4+Decisions!G5+Decisions!G6+Decisions!G7+Decisions!G8 -> 1149.6209 | G3: =Decisions!H3+Decisions!H4+Decisions!H5+Decisions!H6+Decisions!H7+Decisions!H8 -> 1149.6209 | H3: =Decisions!I3+Decisions!I4+Decisions!I5+Decisions!I6+Decisions!I7+Decisions!I8 -> 1149.6209 | I3: =Decisions!J3+Decisions!J4+Decisions!J5+Decisions!J6+Decisions!J7+Decisions!J8 -> 1149.6209 | ... L3: =Decisions!M3+Decisions!M4+Decisions!M5+Decisions!M6+Decisions!M7+Decisions!M8 -> 1149.6209
A4: Revenue total ($M) | B4: =Financials!B9 -> 1187.9999 | C4: =Financials!C9 -> 1091.3394 | D4: =Financials!D9 -> 1002.5952 | E4: =Financials!E9 -> 932.7773 | F4: =Financials!F9 -> 878.89954 | G4: =Financials!G9 -> 840.62058 | H4: =Financials!H9 -> 802.66394 | I4: =Financials!I9 -> 765.00171 | ... L4: =Financials!L9 -> 643.76037
A5: EBITDA total ($M) | B5: =Financials!B8 -> 176.69999 | C5: =Financials!C8 -> 142.14031 | D5: =Financials!D8 -> 103.10616 | E5: =Financials!E8 -> 72.626035 | F5: =Financials!F8 -> 49.050047 | G5: =Financials!G8 -> 32.987575 | H5: =Financials!H8 -> 11.874922 | I5: =Financials!I8 -> -13.759882 | ... L5: =Financials!L8 -> -118.72189
A6: Depreciation ($M) | B6: =Financials!B11 -> 60 | C6: =Financials!C11 -> 65 | D6: =Financials!D11 -> 70 | E6: =Financials!E11 -> 78 | F6: =Financials!F11 -> 88 | G6: =Financials!G11 -> 100 | H6: =Financials!H11 -> 115 | I6: =Financials!I11 -> 130 | ... L6: =Financials!L11 -> 195
A7: Capex total ($M) | B7: =Financials!B10 -> 0 | C7: =Financials!C10 -> 0 | D7: =Financials!D10 -> 0 | E7: =Financials!E10 -> 0 | F7: =Financials!F10 -> 0 | G7: =Financials!G10 -> 0 | H7: =Financials!H10 -> 0 | I7: =Financials!I10 -> 0 | ... L7: =Financials!L10 -> 0
A8: FCF ($M) | B8: =Financials!B12 -> 145.19099 | C8: =Financials!C12 -> 121.31243 | D8: =Financials!D12 -> 94.1675 | E8: =Financials!E12 -> 74.077005 | F8: =Financials!F12 -> 59.566534 | G8: =Financials!G12 -> 51.08093 | H8: =Financials!H12 -> 39.718693 | I8: =Financials!I12 -> 25.055286 | ... L8: =Financials!L12 -> -34.01698
A9: Discount factor | B9: =Financials!B17 -> 1 | C9: =Financials!C17 -> 0.91332542 | D9: =Financials!D17 -> 0.83416332 | E9: =Financials!E17 -> 0.76186256 | F9: =Financials!F17 -> 0.69582844 | G9: =Financials!G17 -> 0.6355178 | H9: =Financials!H17 -> 0.58043456 | I9: =Financials!I17 -> 0.53012564 | ... L9: =Financials!L17 -> 0.40388288
A10: Discounted FCF ($M) | B10: =Financials!B18 -> 145.19099 | C10: =Financials!C18 -> 110.79772 | D10: =Financials!D18 -> 78.551074 | E10: =Financials!E18 -> 56.436497 | F10: =Financials!F18 -> 41.448089 | G10: =Financials!G18 -> 32.46284 | H10: =Financials!H18 -> 23.054102 | I10: =Financials!I18 -> 13.28245 | ... L10: =Financials!L18 -> -13.738876
A12: Revenue by line ($M)
A13: Revenue USS | B13: =Dynamics!C9 -> 469.99998 | C13: =Dynamics!D9 -> 434.1249 | D13: =Dynamics!E9 -> 400.98815 | E13: =Dynamics!F9 -> 370.38072 | F13: =Dynamics!G9 -> 349.57356 | G13: =Dynamics!H9 -> 330.35461 | H13: =Dynamics!I9 -> 312.60264 | I13: =Dynamics!J9 -> 296.20568 | ... L13: =Dynamics!M9 -> 245.63973
A14: Revenue SPN | B14: =Dynamics!C20 -> 180 | C14: =Dynamics!D20 -> 165.4209 | D14: =Dynamics!E20 -> 152.02263 | E14: =Dynamics!F20 -> 146.70706 | F14: =Dynamics!G20 -> 141.82202 | G14: =Dynamics!H20 -> 137.33265 | H14: =Dynamics!I20 -> 131.45752 | I14: =Dynamics!J20 -> 124.30886 | ... L14: =Dynamics!M20 -> 98.363484
A15: Revenue FIS | B15: =Dynamics!C31 -> 79.99995 | C15: =Dynamics!D31 -> 73.1472 | D15: =Dynamics!E31 -> 66.881411 | E15: =Dynamics!F31 -> 61.152349 | F15: =Dynamics!G31 -> 58.713039 | G15: =Dynamics!H31 -> 56.48268 | H15: =Dynamics!I31 -> 54.443374 | I15: =Dynamics!J31 -> 52.578754 | ... L15: =Dynamics!M31 -> 44.718583
A16: Revenue EMS | B16: =Dynamics!C42 -> 36 | C16: =Dynamics!D42 -> 33.42006 | D16: =Dynamics!E42 -> 31.025011 | E16: =Dynamics!F42 -> 28.801604 | F16: =Dynamics!G42 -> 26.737537 | G16: =Dynamics!H42 -> 31.818891 | H16: =Dynamics!I42 -> 36.536091 | I16: =Dynamics!J42 -> 40.915232 | ... L16: =Dynamics!M42 -> 51.208394
A17: Revenue ANS | B17: =Dynamics!C53 -> 350 | C17: =Dynamics!D53 -> 318.38625 | D17: =Dynamics!E53 -> 289.62801 | E17: =Dynamics!F53 -> 268.13236 | F17: =Dynamics!G53 -> 248.57831 | G17: =Dynamics!H53 -> 230.79047 | H17: =Dynamics!I53 -> 213.44307 | I17: =Dynamics!J53 -> 196.49633 | ... L17: =Dynamics!M53 -> 149.14565
A18: Revenue NPS | B18: =Dynamics!C64 -> 72 | C18: =Dynamics!D64 -> 66.84012 | D18: =Dynamics!E64 -> 62.050023 | E18: =Dynamics!F64 -> 57.603208 | F18: =Dynamics!G64 -> 53.475074 | G18: =Dynamics!H64 -> 53.841283 | H18: =Dynamics!I64 -> 54.181247 | I18: =Dynamics!J64 -> 54.496848 | ... L18: =Dynamics!M64 -> 54.684538
A20: EBITDA by line ($M)
A21: EBITDA USS | B21: =Dynamics!C11 -> 25.499997 | C21: =Dynamics!D11 -> 21.440493 | D21: =Dynamics!E11 -> 14.757264 | E21: =Dynamics!F11 -> 7.1653497 | F21: =Dynamics!G11 -> 6.5609628 | G21: =Dynamics!H11 -> 4.1814404 | H21: =Dynamics!I11 -> 1.2437381 | I21: =Dynamics!J11 -> -2.1003136 | ... L21: =Dynamics!M11 -> -22.137956
A22: EBITDA SPN | B22: =Dynamics!C22 -> 28 | C22: =Dynamics!D22 -> 22.313178 | D22: =Dynamics!E22 -> 15.575611 | E22: =Dynamics!F22 -> 15.923169 | F22: =Dynamics!G22 -> 14.866853 | G22: =Dynamics!H22 -> 13.492195 | H22: =Dynamics!I22 -> 10.110548 | I22: =Dynamics!J22 -> 4.9080792 | ... L22: =Dynamics!M22 -> -17.92509
A23: EBITDA FIS | B23: =Dynamics!C33 -> 5.99999 | C23: =Dynamics!D33 -> 2.7274259 | D23: =Dynamics!E33 -> -0.68704438 | E23: =Dynamics!F33 -> -5.1226529 | F23: =Dynamics!G33 -> -6.7175488 | G23: =Dynamics!H33 -> -8.4774575 | H23: =Dynamics!I33 -> -10.365315 | I23: =Dynamics!J33 -> -12.355394 | ... L23: =Dynamics!M33 -> -21.948822
A24: EBITDA EMS | B24: =Dynamics!C44 -> 2.2 | C24: =Dynamics!D44 -> 0.68117115 | D24: =Dynamics!E44 -> -2.2051542 | E24: =Dynamics!F44 -> -6.3015164 | F24: =Dynamics!G44 -> -11.522405 | G24: =Dynamics!H44 -> -10.819791 | H24: =Dynamics!I44 -> -11.66109 | I24: =Dynamics!J44 -> -13.989914 | ... L24: =Dynamics!M44 -> -25.514528
A25: EBITDA ANS | B25: =Dynamics!C55 -> 105 | C25: =Dynamics!D55 -> 86.606414 | D25: =Dynamics!E55 -> 69.505298 | E25: =Dynamics!F55 -> 58.336105 | F25: =Dynamics!G55 -> 46.953548 | G25: =Dynamics!H55 -> 36.32055 | H25: =Dynamics!I55 -> 25.223595 | I25: =Dynamics!J55 -> 13.716273 | ... L25: =Dynamics!M55 -> -21.443567
A26: EBITDA NPS | B26: =Dynamics!C66 -> 10 | C26: =Dynamics!D66 -> 8.3716288 | D26: =Dynamics!E66 -> 6.1601901 | E26: =Dynamics!F66 -> 2.62558 | F26: =Dynamics!G66 -> -1.091364 | G26: =Dynamics!H66 -> -1.7093619 | H26: =Dynamics!I66 -> -2.6765542 | I26: =Dynamics!J66 -> -3.9386123 | ... L26: =Dynamics!M66 -> -9.7519273
A28: Volume (Q) by line (kt)
A29: Q USS | B29: =Dynamics!C3 -> 234.99999 | C29: =Dynamics!D3 -> 219.255 | D29: =Dynamics!E3 -> 204.56492 | E29: =Dynamics!F3 -> 190.85907 | F29: =Dynamics!G3 -> 178.07151 | G29: =Dynamics!H3 -> 166.14072 | H29: =Dynamics!I3 -> 155.00929 | I29: =Dynamics!J3 -> 144.62367 | ... L29: =Dynamics!M3 -> 117.45846
A30: Q SPN | B30: =Dynamics!C14 -> 120 | C30: =Dynamics!D14 -> 111.96 | D30: =Dynamics!E14 -> 104.45868 | E30: =Dynamics!F14 -> 97.459948 | F30: =Dynamics!G14 -> 90.930132 | G30: =Dynamics!H14 -> 84.837813 | H30: =Dynamics!I14 -> 79.15368 | I30: =Dynamics!J14 -> 73.850383 | ... L30: =Dynamics!M14 -> 59.978788
A31: Q FIS | B31: =Dynamics!C25 -> 39.999975 | C31: =Dynamics!D25 -> 37.32 | D31: =Dynamics!E25 -> 34.81956 | E31: =Dynamics!F25 -> 32.486649 | F31: =Dynamics!G25 -> 30.310044 | G31: =Dynamics!H25 -> 28.279271 | H31: =Dynamics!I25 -> 26.38456 | I31: =Dynamics!J25 -> 24.616794 | ... L31: =Dynamics!M25 -> 19.992929
A32: Q EMS | B32: =Dynamics!C36 -> 6 | C32: =Dynamics!D36 -> 5.598 | D32: =Dynamics!E36 -> 5.222934 | E32: =Dynamics!F36 -> 4.8729974 | F32: =Dynamics!G36 -> 4.5465066 | G32: =Dynamics!H36 -> 4.2418907 | H32: =Dynamics!I36 -> 3.957684 | I32: =Dynamics!J36 -> 3.6925192 | ... L32: =Dynamics!M36 -> 2.9989394
A33: Q ANS | B33: =Dynamics!C47 -> 350 | C33: =Dynamics!D47 -> 326.55 | D33: =Dynamics!E47 -> 304.67115 | E33: =Dynamics!F47 -> 284.25818 | F33: =Dynamics!G47 -> 265.21288 | G33: =Dynamics!H47 -> 247.44362 | H33: =Dynamics!I47 -> 230.8649 | I33: =Dynamics!J47 -> 215.39695 | ... L33: =Dynamics!M47 -> 174.93813
A34: Q NPS | B34: =Dynamics!C58 -> 12 | C34: =Dynamics!D58 -> 11.196 | D34: =Dynamics!E58 -> 10.445868 | E34: =Dynamics!F58 -> 9.7459948 | F34: =Dynamics!G58 -> 9.0930132 | G34: =Dynamics!H58 -> 8.4837813 | H34: =Dynamics!I58 -> 7.915368 | I34: =Dynamics!J58 -> 7.3850383 | ... L34: =Dynamics!M58 -> 5.9978788
A36: Capacity (K) by line (kt)
A37: K USS | B37: =Dynamics!C2 -> 235 | C37: =Dynamics!D2 -> 219.255 | D37: =Dynamics!E2 -> 204.56492 | E37: =Dynamics!F2 -> 190.85907 | F37: =Dynamics!G2 -> 178.07151 | G37: =Dynamics!H2 -> 166.14072 | H37: =Dynamics!I2 -> 155.00929 | I37: =Dynamics!J2 -> 144.62367 | ... L37: =Dynamics!M2 -> 117.45846
A38: K SPN | B38: =Dynamics!C13 -> 120 | C38: =Dynamics!D13 -> 111.96 | D38: =Dynamics!E13 -> 104.45868 | E38: =Dynamics!F13 -> 97.459948 | F38: =Dynamics!G13 -> 90.930132 | G38: =Dynamics!H13 -> 84.837813 | H38: =Dynamics!I13 -> 79.15368 | I38: =Dynamics!J13 -> 73.850383 | ... L38: =Dynamics!M13 -> 59.978788
A39: K FIS | B39: =Dynamics!C24 -> 40 | C39: =Dynamics!D24 -> 37.32 | D39: =Dynamics!E24 -> 34.81956 | E39: =Dynamics!F24 -> 32.486649 | F39: =Dynamics!G24 -> 30.310044 | G39: =Dynamics!H24 -> 28.279271 | H39: =Dynamics!I24 -> 26.38456 | I39: =Dynamics!J24 -> 24.616794 | ... L39: =Dynamics!M24 -> 19.992929
A40: K EMS | B40: =Dynamics!C35 -> 6 | C40: =Dynamics!D35 -> 5.598 | D40: =Dynamics!E35 -> 5.222934 | E40: =Dynamics!F35 -> 4.8729974 | F40: =Dynamics!G35 -> 4.5465066 | G40: =Dynamics!H35 -> 4.2418907 | H40: =Dynamics!I35 -> 3.957684 | I40: =Dynamics!J35 -> 3.6925192 | ... L40: =Dynamics!M35 -> 2.9989394
A41: K ANS | B41: =Dynamics!C46 -> 350 | C41: =Dynamics!D46 -> 326.55 | D41: =Dynamics!E46 -> 304.67115 | E41: =Dynamics!F46 -> 284.25818 | F41: =Dynamics!G46 -> 265.21288 | G41: =Dynamics!H46 -> 247.44362 | H41: =Dynamics!I46 -> 230.8649 | I41: =Dynamics!J46 -> 215.39695 | ... L41: =Dynamics!M46 -> 174.93813
A42: K NPS | B42: =Dynamics!C57 -> 12 | C42: =Dynamics!D57 -> 11.196 | D42: =Dynamics!E57 -> 10.445868 | E42: =Dynamics!F57 -> 9.7459948 | F42: =Dynamics!G57 -> 9.0930132 | G42: =Dynamics!H57 -> 8.4837813 | H42: =Dynamics!I57 -> 7.915368 | I42: =Dynamics!J57 -> 7.3850383 | ... L42: =Dynamics!M57 -> 5.9978788
A45: Headline
A46: WACC | B46: =Financials!B15 -> 0.0949
...
